Workbook

Sheet اقرأني أولاً
B2: دليل اختبار برنامج إدارة فروع القرآن الكريم — الإصدار 1.4.0-beta.1
B3: شكراً لتطوعك! هدفنا اكتشاف الأخطاء قبل توزيع البرنامج على الفروع. لا تحتاج أي خبرة تقنية: اتبع الخطوات، وقارن ما تراه بالنتيجة المتوقعة، وسجّل ما وجدت.
B5: معلومات التواصل (يملؤها المنسق)
B6: المنسق
B7: الهاتف / واتساب
B8: رابط تحميل البرنامج
B9: رابط فيديوهات الشرح
B10: آخر أجل للاختبار
B12: كيف أعمل؟
B13: 1. سجّل نفسك | C13: في تبويب «المختبرون» اكتب اسمك وهاتفك ونوع جهازك في أول سطر فارغ.
B14: 2. احجز قسماً | C14: في تبويب «الأقسام» اختر قسماً حالته «متاح للحجز»، واختر اسمك في عمود «المختبِر المسؤول». ابدأ بقسم «التثبيت وأول تشغيل» إن كان جهازك جديداً. يمكنك حجز أكثر من قسم.
B15: 3. نفّذ الاختبارات | C15: في تبويب «الاختبارات» تظهر اختباراتك باسمك (يمكنك تصفية العمود «المختبِر»). ابدأ بالأولوية «أساسي». اتبع «الخطوات» واحدة واحدة، ثم قارن ما حدث بـ «النتيجة المتوقعة».
B16: 4. حدّث الحالة | C16: اختر الحالة من القائمة في عمود «الحالة» واكتب تاريخ اليوم. إن كان هناك شيء غريب اكتبه في «ملاحظات المختبِر» حتى لو نجح الاختبار.
B17: 5. سجّل الأخطاء | C17: إن فشل اختبار: أضف سطراً في «الأخطاء والملاحظات» واكتب رقم الخطأ (مثلاً B-004) في عمود «رقم الخطأ» في سطر الاختبار.
B18: 6. تابع التقدم | C18: تبويب «المتابعة» يحسب التقدم تلقائياً لكل قسم ولكل مختبِر.
B20: معنى الحالات
B21: لم يبدأ | C21: لم أنفذ الاختبار بعد.
B22: قيد التنفيذ | C22: بدأت ولم أكمل.
B23: نجح | C23: كل شيء حدث كما في «النتيجة المتوقعة».
B24: فشل | C24: حدث شيء مختلف عن المتوقع — سجّل خطأً.
B25: متوقف | C25: لم أستطع إكمال الاختبار (خطأ سابق يمنعني، أو ينقصني شيء). اكتب السبب في الملاحظات.
B27: درجة خطورة الخطأ
B28: عاجل | C28: يمنع العمل، أو يُضيّع بيانات، أو يُظهر مبالغ مالية خاطئة.
B29: مهم | C29: وظيفة لا تعمل كما يجب، لكن يمكن إكمال العمل بطريقة أخرى.
B30: بسيط | C30: نص خاطئ، شكل غير مرتب، إزعاج بسيط.
B31: اقتراح | C31: فكرة لتحسين البرنامج.
B33: مثال على تسجيل خطأ جيد
B34: رقم الاختبار | C34: FEE-02
B35: ماذا فعلت؟ | C35: سجّلت دفعة 20 د.ت للطالب «يوسف بن أحمد» الذي عليه 50 د.ت، نقداً، رقم الوصل R-0005.
B36: ماذا حدث؟ | C36: ظهرت رسالة النجاح لكن المتبقي بقي 50 د.ت، ولم يتغير إلا بعد إغلاق البرنامج وفتحه.
B37: ماذا كنت تتوقع؟ | C37: أن يصبح المتبقي 30 د.ت مباشرة.
B38: الخطورة | C38: مهم
B39: لقطة الشاشة | C39: رابط الصورة على Google Drive، أو «أرسلتها على واتساب».
B41: نصائح مهمة
B42: • | C42: استعمل بيانات وهمية فقط (أسماء وأرقام من خيالك). لا تُدخل بيانات أشخاص حقيقيين.
B43: • | C43: لقطة الشاشة في Windows: اضغط Windows + Shift + S ثم حدد الجزء المطلوب، والصقه في رسالة واتساب أو ارفعه إلى Drive.
B44: • | C44: إن ظهرت نافذة حماية Windows عند التثبيت: «مزيد من المعلومات» ثم «تشغيل على أي حال».
B45: • | C45: لا تحذف أسطراً ولا أعمدة في هذا الملف. الخلايا الصفراء لك، والخلايا الرمادية تُحسب تلقائياً.
B46: • | C46: الأقسام مستقلة: كل مختبِر يعمل على نسخته من البرنامج في جهازه. المتطلبات المسبقة لكل قسم مكتوبة في تبويب الأقسام.
B47: • | C47: إن وجدت شيئاً غير مفهوم في البرنامج فهذا بحد ذاته ملاحظة مفيدة — سجّلها كـ «اقتراح».
...

Sheet الأقسام
A1: الرمز | B1: القسم | C1: ما يغطيه | D1: المدة (دقيقة) | E1: الحساب المطلوب | F1: المتطلبات المسبقة | G1: فيديو الشرح | H1: المختبِر المسؤول | I1: تاريخ الحجز | J1: عدد الاختبارات | K1: نجح | L1: فشل | M1: متوقف | N1: المنجز | O1: التقدم | P1: الحالة
A2: INS | B2: التثبيت وأول تشغيل | C2: تثبيت البرنامج، إنشاء حساب المدير، تسجيل الدخول والخروج، الدليل التعريفي، صفحة «حول التطبيق» | D2: 40 | E2: مدير النظام | F2: جهاز Windows وملف التثبيت | G2: الفصل 1 | J2: =COUNTIF(الاختبارات!$B$2:$B$1000,A2) -> 11 | K2: =COUNTIFS(الاختبارات!$B$2:$B$1000,A2,الاختبارات!$J$2:$J$1000,"نجح") -> 0 | L2: =COUNTIFS(الاختبارات!$B$2:$B$1000,A2,الاختبارات!$J$2:$J$1000,"فشل") -> 0 | M2: =COUNTIFS(الاختبارات!$B$2:$B$1000,A2,الاختبارات!$J$2:$J$1000,"متوقف") -> 0 | N2: =K2+L2 -> 0 | O2: =IF(J2=0,0,N2/J2) -> 0 | P2: =IF(H2="","متاح للحجز",IF(N2=J2,"مكتمل","قيد الاختبار")) -> متاح للحجز
A3: SET | B3: الإعدادات والفئات العمرية | C3: بيانات الجمعية، الشعارات، إعدادات الرسوم والسنة الدراسية، الفئات العمرية | D3: 45 | E3: مدير النظام | F3: إكمال قسم التثبيت (INS) | G3: الفصل 2 | J3: =COUNTIF(الاختبارات!$B$2:$B$1000,A3) -> 11 | K3: =COUNTIFS(الاختبارات!$B$2:$B$1000,A3,الاختبارات!$J$2:$J$1000,"نجح") -> 0 | L3: =COUNTIFS(الاختبارات!$B$2:$B$1000,A3,الاختبارات!$J$2:$J$1000,"فشل") -> 0 | M3: =COUNTIFS(الاختبارات!$B$2:$B$1000,A3,الاختبارات!$J$2:$J$1000,"متوقف") -> 0 | N3: =K3+L3 -> 0 | O3: =IF(J3=0,0,N3/J3) -> 0 | P3: =IF(H3="","متاح للحجز",IF(N3=J3,"مكتمل","قيد الاختبار")) -> متاح للحجز
A4: USR | B4: المستخدمون والصلاحيات | C4: إضافة المستخدمين بكل الأدوار، التعديل والحذف، الدخول بكل دور والتحقق مما يظهر له، الملف الشخصي وكلمة المرور | D4: 60 | E4: مدير النظام + الأدوار الأخرى | F4: إكمال قسم التثبيت (INS) | J4: =COUNTIF(الاختبارات!$B$2:$B$1000,A4) -> 13 | K4: =COUNTIFS(الاختبارات!$B$2:$B$1000,A4,الاختبارات!$J$2:$J$1000,"نجح") -> 0 | L4: =COUNTIFS(الاختبارات!$B$2:$B$1000,A4,الاختبارات!$J$2:$J$1000,"فشل") -> 0 | M4: =COUNTIFS(الاختبارات!$B$2:$B$1000,A4,الاختبارات!$J$2:$J$1000,"متوقف") -> 0 | N4: =K4+L4 -> 0 | O4: =IF(J4=0,0,N4/J4) -> 0 | P4: =IF(H4="","متاح للحجز",IF(N4=J4,"مكتمل","قيد الاختبار")) -> متاح للحجز
A5: TCH | B5: المعلمون | C5: إضافة المعلمين والتحقق من الحقول، البحث والتصفية، التفاصيل، التعديل والحذف، التصدير والاستيراد | D5: 35 | E5: مدير النظام | F5: إكمال قسم التثبيت (INS) | G5: الفصل 3 | J5: =COUNTIF(الاختبارات!$B$2:$B$1000,A5) -> 8 | K5: =COUNTIFS(الاختبارات!$B$2:$B$1000,A5,الاختبارات!$J$2:$J$1000,"نجح") -> 0 | L5: =COUNTIFS(الاختبارات!$B$2:$B$1000,A5,الاختبارات!$J$2:$J$1000,"فشل") -> 0 | M5: =COUNTIFS(الاختبارات!$B$2:$B$1000,A5,الاختبارات!$J$2:$J$1000,"متوقف") -> 0 | N5: =K5+L5 -> 0 | O5: =IF(J5=0,0,N5/J5) -> 0 | P5: =IF(H5="","متاح للحجز",IF(N5=J5,"مكتمل","قيد الاختبار")) -> متاح للحجز
A6: STU | B6: الطلاب | C6: إضافة الطلاب بكل أنواعهم، التحقق من الحقول، الحفظ القرآني، البحث والتصفية، التعديل والحذف، التصدير والاستيراد | D6: 70 | E6: مدير النظام | F6: إكمال قسم التثبيت (INS)؛ يفضل وجود فصل واحد على الأقل | G6: الفصل 4 | J6: =COUNTIF(الاختبارات!$B$2:$B$1000,A6) -> 16 | K6: =COUNTIFS(الاختبارات!$B$2:$B$1000,A6,الاختبارات!$J$2:$J$1000,"نجح") -> 0 | L6: =COUNTIFS(الاختبارات!$B$2:$B$1000,A6,الاختبارات!$J$2:$J$1000,"فشل") -> 0 | M6: =COUNTIFS(الاختبارات!$B$2:$B$1000,A6,الاختبارات!$J$2:$J$1000,"متوقف") -> 0 | N6: =K6+L6 -> 0 | O6: =IF(J6=0,0,N6/J6) -> 0 | P6: =IF(H6="","متاح للحجز",IF(N6=J6,"مكتمل","قيد الاختبار")) -> متاح للحجز
A7: CLS | B7: الفصول وتسجيل الطلاب | C7: إنشاء الفصول والمواعيد، الحالات، المعلوم الخاص، تسجيل الطلاب وإلغاؤه، تحذيرات السن والجنس، فصول اليوم | D7: 55 | E7: مدير النظام | F7: معلم واحد و5 طلاب على الأقل بأعمار وأجناس مختلفة | G7: الفصل 5 | J7: =COUNTIF(الاختبارات!$B$2:$B$1000,A7) -> 12 | K7: =COUNTIFS(الاختبارات!$B$2:$B$1000,A7,الاختبارات!$J$2:$J$1000,"نجح") -> 0 | L7: =COUNTIFS(الاختبارات!$B$2:$B$1000,A7,الاختبارات!$J$2:$J$1000,"فشل") -> 0 | M7: =COUNTIFS(الاختبارات!$B$2:$B$1000,A7,الاختبارات!$J$2:$J$1000,"متوقف") -> 0 | N7: =K7+L7 -> 0 | O7: =IF(J7=0,0,N7/J7) -> 0 | P7: =IF(H7="","متاح للحجز",IF(N7=J7,"مكتمل","قيد الاختبار")) -> متاح للحجز
A8: ATT | B8: الحضور والغياب | C8: تسجيل الحضور، القفل والتعديل، السجلات المحفوظة، التواريخ السابقة، التصدير والاستيراد | D8: 35 | E8: مدير النظام أو مشرف حصص | F8: فصل نشط فيه 3 طلاب على الأقل | G8: الفصل 6 | J8: =COUNTIF(الاختبارات!$B$2:$B$1000,A8) -> 9 | K8: =COUNTIFS(الاختبارات!$B$2:$B$1000,A8,الاختبارات!$J$2:$J$1000,"نجح") -> 0 | L8: =COUNTIFS(الاختبارات!$B$2:$B$1000,A8,الاختبارات!$J$2:$J$1000,"فشل") -> 0 | M8: =COUNTIFS(الاختبارات!$B$2:$B$1000,A8,الاختبارات!$J$2:$J$1000,"متوقف") -> 0 | N8: =K8+L8 -> 0 | O8: =IF(J8=0,0,N8/J8) -> 0 | P8: =IF(H8="","متاح للحجز",IF(N8=J8,"مكتمل","قيد الاختبار")) -> متاح للحجز
A9: FEE | B9: رسوم الطلاب والدفعات | C9: توليد الرسوم، الدفعات الجزئية والكاملة والزائدة، الوصل، الحذف والاسترجاع، المعفى والمكفول والخصم، الفصول ذات المعلوم الخاص، الدفع السنوي، فئة الرسوم | D9: 90 | E9: مدير النظام أو مسؤول مالي | F9: رسوم مضبوطة في الإعدادات، وطلاب مسجلون في فصول | G9: الفصل 7 | J9: =COUNTIF(الاختبارات!$B$2:$B$1000,A9) -> 21 | K9: =COUNTIFS(الاختبارات!$B$2:$B$1000,A9,الاختبارات!$J$2:$J$1000,"نجح") -> 0 | L9: =COUNTIFS(الاختبارات!$B$2:$B$1000,A9,الاختبارات!$J$2:$J$1000,"فشل") -> 0 | M9: =COUNTIFS(الاختبارات!$B$2:$B$1000,A9,الاختبارات!$J$2:$J$1000,"متوقف") -> 0 | N9: =K9+L9 -> 0 | O9: =IF(J9=0,0,N9/J9) -> 0 | P9: =IF(H9="","متاح للحجز",IF(N9=J9,"مكتمل","قيد الاختبار")) -> متاح للحجز
A10: FIN | B10: المداخيل والمصاريف ولوحة التحكم المالية | C10: تسجيل المداخيل والمصاريف، قاعدة 500 دينار، الوصولات، التعديل والحذف، الفئات، التصفية، لوحة التحكم والفترات | D10: 60 | E10: مدير النظام أو مسؤول مالي | F10: إكمال قسم التثبيت (INS) | G10: الفصل 8 | J10: =COUNTIF(الاختبارات!$B$2:$B$1000,A10) -> 12 | K10: =COUNTIFS(الاختبارات!$B$2:$B$1000,A10,الاختبارات!$J$2:$J$1000,"نجح") -> 0 | L10: =COUNTIFS(الاختبارات!$B$2:$B$1000,A10,الاختبارات!$J$2:$J$1000,"فشل") -> 0 | M10: =COUNTIFS(الاختبارات!$B$2:$B$1000,A10,الاختبارات!$J$2:$J$1000,"متوقف") -> 0 | N10: =K10+L10 -> 0 | O10: =IF(J10=0,0,N10/J10) -> 0 | P10: =IF(H10="","متاح للحجز",IF(N10=J10,"مكتمل","قيد الاختبار")) -> متاح للحجز
A11: INV | B11: الجرد والتبرعات العينية | C11: أصناف المخزون، القيمة الإجمالية، التبرعات العينية، التعديل والحذف، تصدير سجل الجرد | D11: 30 | E11: مدير النظام أو مسؤول مالي | F11: إكمال قسم التثبيت (INS) | J11: =COUNTIF(الاختبارات!$B$2:$B$1000,A11) -> 6 | K11: =COUNTIFS(الاختبارات!$B$2:$B$1000,A11,الاختبارات!$J$2:$J$1000,"نجح") -> 0 | L11: =COUNTIFS(الاختبارات!$B$2:$B$1000,A11,الاختبارات!$J$2:$J$1000,"فشل") -> 0 | M11: =COUNTIFS(الاختبارات!$B$2:$B$1000,A11,الاختبارات!$J$2:$J$1000,"متوقف") -> 0 | N11: =K11+L11 -> 0 | O11: =IF(J11=0,0,N11/J11) -> 0 | P11: =IF(H11="","متاح للحجز",IF(N11=J11,"مكتمل","قيد الاختبار")) -> متاح للحجز
A12: REP | B12: التقارير والتصدير | C12: التقرير المالي (Word)، سجل المحاسبة (Excel)، سجل الجرد، تصدير قوائم الطلاب والمعلمين والفصول والحضور، التحقق من محتوى الملفات | D12: 45 | E12: مدير النظام أو مسؤول مالي | F12: بيانات مالية وطلاب مسجلون (من الأقسام السابقة) | J12: =COUNTIF(الاختبارات!$B$2:$B$1000,A12) -> 6 | K12: =COUNTIFS(الاختبارات!$B$2:$B$1000,A12,الاختبارات!$J$2:$J$1000,"نجح") -> 0 | L12: =COUNTIFS(الاختبارات!$B$2:$B$1000,A12,الاختبارات!$J$2:$J$1000,"فشل") -> 0 | M12: =COUNTIFS(الاختبارات!$B$2:$B$1000,A12,الاختبارات!$J$2:$J$1000,"متوقف") -> 0 | N12: =K12+L12 -> 0 | O12: =IF(J12=0,0,N12/J12) -> 0 | P12: =IF(H12="","متاح للحجز",IF(N12=J12,"مكتمل","قيد الاختبار")) -> متاح للحجز
A13: BAK | B13: النسخ الاحتياطي والاستعادة | C13: رمز النقل، النسخ اليدوي والتلقائي، تذكير النسخ، استعادة قاعدة بيانات، النقل إلى جهاز آخر | D13: 45 | E13: مدير النظام | F13: بعض البيانات في البرنامج؛ مفتاح USB أو مجلد فارغ | G13: الفصل 9 | J13: =COUNTIF(الاختبارات!$B$2:$B$1000,A13) -> 8 | K13: =COUNTIFS(الاختبارات!$B$2:$B$1000,A13,الاختبارات!$J$2:$J$1000,"نجح") -> 0 | L13: =COUNTIFS(الاختبارات!$B$2:$B$1000,A13,الاختبارات!$J$2:$J$1000,"فشل") -> 0 | M13: =COUNTIFS(الاختبارات!$B$2:$B$1000,A13,الاختبارات!$J$2:$J$1000,"متوقف") -> 0 | N13: =K13+L13 -> 0 | O13: =IF(J13=0,0,N13/J13) -> 0 | P13: =IF(H13="","متاح للحجز",IF(N13=J13,"مكتمل","قيد الاختبار")) -> متاح للحجز
A14: GEN | B14: الاستعمال العام والاستكشاف الحر | C14: القائمة الجانبية، حجم النافذة، الكتابة بالعربية، الإغلاق وإعادة الفتح، سرعة البرنامج مع بيانات كثيرة، الاستعمال الحر | D14: 45 | E14: كل الأدوار | F14: بيانات من الأقسام الأخرى | J14: =COUNTIF(الاختبارات!$B$2:$B$1000,A14) -> 6 | K14: =COUNTIFS(الاختبارات!$B$2:$B$1000,A14,الاختبارات!$J$2:$J$1000,"نجح") -> 0 | L14: =COUNTIFS(الاختبارات!$B$2:$B$1000,A14,الاختبارات!$J$2:$J$1000,"فشل") -> 0 | M14: =COUNTIFS(الاختبارات!$B$2:$B$1000,A14,الاختبارات!$J$2:$J$1000,"متوقف") -> 0 | N14: =K14+L14 -> 0 | O14: =IF(J14=0,0,N14/J14) -> 0 | P14: =IF(H14="","متاح للحجز",IF(N14=J14,"مكتمل","قيد الاختبار")) -> متاح للحجز

Sheet الاختبارات
A1: الرقم | B1: القسم | C1: اسم القسم | D1: الاختبار | E1: المتطلبات المسبقة | F1: الخطوات | G1: النتيجة المتوقعة | H1: الأولوية | I1: المختبِر | J1: الحالة | K1: تاريخ الاختبار | L1: ملاحظات المختبِر | M1: رقم الخطأ
A2: INS-01 | B2: INS | C2: =IFERROR(INDEX(الأقسام!$B$2:$B$14,MATCH(B2,الأقسام!$A$2:$A$14,0)),"") -> التثبيت وأول تشغيل | D2: تثبيت البرنامج | E2: ملف التثبيت (exe) | F2: 1. شغّل ملف التثبيت. 2. إن ظهرت نافذة حماية Windows (SmartScreen) اضغط «مزيد من المعلومات» ثم «تشغيل على أي حال». 3. أكمل التثبيت. | G2: يكتمل التثبيت ويظهر اختصار البرنامج، ويفتح البرنامج على شاشة «إنشاء مدير النظام». | H2: أساسي | I2: =IFERROR(INDEX(الأقسام!$H$2:$H$14,MATCH(B2,الأقسام!$A$2:$A$14,0))&"","") | J2: لم يبدأ
A3: INS-02 | B3: INS | C3: =IFERROR(INDEX(الأقسام!$B$2:$B$14,MATCH(B3,الأقسام!$A$2:$A$14,0)),"") -> التثبيت وأول تشغيل | D3: رفض بيانات غير صالحة عند إنشاء المدير | E3: أول تشغيل | F3: 1. اكتب اسم مستخدم بالعربية (مثلاً: احمد). 2. اكتب كلمة مرور قصيرة (3 أحرف). 3. اكتب تأكيداً مختلفاً عن كلمة المرور. 4. اضغط «إنشاء مدير النظام» بعد كل خطأ. | G3: تظهر رسالة خطأ واضحة بالعربية لكل حالة، ولا يُنشأ الحساب. | H3: أساسي | I3: =IFERROR(INDEX(الأقسام!$H$2:$H$14,MATCH(B3,الأقسام!$A$2:$A$14,0))&"","") | J3: لم يبدأ
A4: INS-03 | B4: INS | C4: =IFERROR(INDEX(الأقسام!$B$2:$B$14,MATCH(B4,الأقسام!$A$2:$A$14,0)),"") -> التثبيت وأول تشغيل | D4: إنشاء حساب مدير النظام | E4: أول تشغيل | F4: 1. اكتب اسم مستخدم بالإنجليزية (مثلاً: admin1). 2. اكتب كلمة مرور قوية وأعد كتابتها. 3. اضغط «إنشاء مدير النظام». | G4: يُنشأ الحساب وتظهر شاشة «تسجيل الدخول». لا تظهر شاشة إنشاء المدير مرة أخرى. | H4: أساسي | I4: =IFERROR(INDEX(الأقسام!$H$2:$H$14,MATCH(B4,الأقسام!$A$2:$A$14,0))&"","") | J4: لم يبدأ
A5: INS-04 | B5: INS | C5: =IFERROR(INDEX(الأقسام!$B$2:$B$14,MATCH(B5,الأقسام!$A$2:$A$14,0)),"") -> التثبيت وأول تشغيل | D5: تسجيل الدخول بكلمة مرور خاطئة | E5: حساب المدير موجود | F5: 1. اكتب اسم المستخدم الصحيح وكلمة مرور خاطئة. 2. اضغط «تسجيل الدخول». | G5: رسالة «اسم المستخدم أو كلمة المرور غير صحيحة»، ولا يتم الدخول. | H5: أساسي | I5: =IFERROR(INDEX(الأقسام!$H$2:$H$14,MATCH(B5,الأقسام!$A$2:$A$14,0))&"","") | J5: لم يبدأ
A6: INS-05 | B6: INS | C6: =IFERROR(INDEX(الأقسام!$B$2:$B$14,MATCH(B6,الأقسام!$A$2:$A$14,0)),"") -> التثبيت وأول تشغيل | D6: قفل الدخول بعد 5 محاولات خاطئة | E6: حساب المدير موجود | F6: 1. أدخل كلمة مرور خاطئة 5 مرات متتالية. 2. أدخل بعدها كلمة المرور الصحيحة. 3. انتظر 5 دقائق وأعد المحاولة بكلمة المرور الصحيحة. | G6: بعد 5 محاولات يُقفل الدخول مؤقتاً مع رسالة تذكر مدة الانتظار، حتى مع كلمة المرور الصحيحة. بعد 5 دقائق يتم الدخول بشكل عادي. | H6: مهم | I6: =IFERROR(INDEX(الأقسام!$H$2:$H$14,MATCH(B6,الأقسام!$A$2:$A$14,0))&"","") | J6: لم يبدأ
A7: INS-06 | B7: INS | C7: =IFERROR(INDEX(الأقسام!$B$2:$B$14,MATCH(B7,الأقسام!$A$2:$A$14,0)),"") -> التثبيت وأول تشغيل | D7: تسجيل الدخول بنجاح | E7: حساب المدير موجود | F7: 1. أدخل اسم المستخدم وكلمة المرور الصحيحين. 2. اضغط «تسجيل الدخول». | G7: تفتح «لوحة التحكم الرئيسية»، ويظهر الدليل التعريفي عند أول دخول. | H7: أساسي | I7: =IFERROR(INDEX(الأقسام!$H$2:$H$14,MATCH(B7,الأقسام!$A$2:$A$14,0))&"","") | J7: لم يبدأ
A8: INS-07 | B8: INS | C8: =IFERROR(INDEX(الأقسام!$B$2:$B$14,MATCH(B8,الأقسام!$A$2:$A$14,0)),"") -> التثبيت وأول تشغيل | D8: الدليل التعريفي | E8: أول دخول | F8: 1. تنقّل في الدليل بزري «التالي» و«السابق». 2. اضغط «إيقاف العرض». 3. في الصفحة الرئيسية اضغط «تشغيل دليل الإعداد». 4. جرّب «متابعة» ثم أعد التجربة مع «البدء من البداية». | G8: الدليل يشرح الأقسام بالترتيب، ويختفي عند الإيقاف، ويمكن إعادة تشغيله من الصفحة الرئيسية ومتابعته من آخر خطوة أو من البداية. | H8: مهم | I8: =IFERROR(INDEX(الأقسام!$H$2:$H$14,MATCH(B8,الأقسام!$A$2:$A$14,0))&"","") | J8: لم يبدأ
A9: INS-08 | B9: INS | C9: =IFERROR(INDEX(الأقسام!$B$2:$B$14,MATCH(B9,الأقسام!$A$2:$A$14,0)),"") -> التثبيت وأول تشغيل | D9: الصفحة الرئيسية | E9: تم الدخول | F9: 1. راجع بطاقات الإحصائيات (الطلاب النشطون، المعلمون، الفصول النشطة). 2. جرّب أزرار «إجراءات سريعة». 3. راجع قسم «فصول اليوم». | G9: الأرقام صحيحة (صفر في البداية)، والأزرار السريعة تفتح النماذج الصحيحة، وتظهر رسالة «لا توجد فصول مجدولة لهذا اليوم» عند عدم وجود فصول. | H9: مهم | I9: =IFERROR(INDEX(الأقسام!$H$2:$H$14,MATCH(B9,الأقسام!$A$2:$A$14,0))&"","") | J9: لم يبدأ
A10: INS-09 | B10: INS | C10: =IFERROR(INDEX(الأقسام!$B$2:$B$14,MATCH(B10,الأقسام!$A$2:$A$14,0)),"") -> التثبيت وأول تشغيل | D10: تسجيل الخروج | E10: تم الدخول | F10: 1. اضغط «خروج» أسفل القائمة الجانبية. | G10: العودة إلى شاشة تسجيل الدخول (وليس شاشة إنشاء المدير). | H10: أساسي | I10: =IFERROR(INDEX(الأقسام!$H$2:$H$14,MATCH(B10,الأقسام!$A$2:$A$14,0))&"","") | J10: لم يبدأ
A11: INS-10 | B11: INS | C11: =IFERROR(INDEX(الأقسام!$B$2:$B$14,MATCH(B11,الأقسام!$A$2:$A$14,0)),"") -> التثبيت وأول تشغيل | D11: إغلاق البرنامج وإعادة فتحه | E11: بعض البيانات مسجلة | F11: 1. أضف طالباً (أي بيانات تجريبية). 2. أغلق البرنامج تماماً. 3. أعد فتحه وسجّل الدخول. | G11: البيانات محفوظة، ويُطلب تسجيل الدخول من جديد. | H11: أساسي | I11: =IFERROR(INDEX(الأقسام!$H$2:$H$14,MATCH(B11,الأقسام!$A$2:$A$14,0))&"","") | J11: لم يبدأ
A12: INS-11 | B12: INS | C12: =IFERROR(INDEX(الأقسام!$B$2:$B$14,MATCH(B12,الأقسام!$A$2:$A$14,0)),"") -> التثبيت وأول تشغيل | D12: صفحة «حول التطبيق» | E12: تم الدخول | F12: 1. افتح «حول التطبيق». 2. تصفح تبويبات «عن التطبيق» و«تفاصيل تقنية» و«الدعم والمساهمة». | G12: تظهر المعلومات ورقم الإصدار (1.4.0-beta.1) بدون أخطاء، والروابط تعمل. | H12: إضافي | I12: =IFERROR(INDEX(الأقسام!$H$2:$H$14,MATCH(B12,الأقسام!$A$2:$A$14,0))&"","") | J12: لم يبدأ
A13: SET-01 | B13: SET | C13: =IFERROR(INDEX(الأقسام!$B$2:$B$14,MATCH(B13,الأقسام!$A$2:$A$14,0)),"") -> الإعدادات والفئات العمرية | D13: بيانات الجمعية/الفرع | E13: تم الدخول كمدير | F13: 1. الإعدادات ← «بيانات الجمعية/الفرع». 2. املأ اسم الجمعية الوطنية والفرع الجهوي والمحلي واسم الرئيس. 3. اضغط «حفظ جميع التغييرات». 4. انتقل إلى صفحة أخرى ثم ارجع. | G13: رسالة نجاح، والبيانات تبقى محفوظة بعد التنقل وبعد إعادة فتح البرنامج. | H13: أساسي | I13: =IFERROR(INDEX(الأقسام!$H$2:$H$14,MATCH(B13,الأقسام!$A$2:$A$14,0))&"","") | J13: لم يبدأ
... A16: SET-04 | B16: SET | C16: =IFERROR(INDEX(الأقسام!$B$2:$B$14,MATCH(B16,الأقسام!$A$2:$A$14,0)),"") -> الإعدادات والفئات العمرية | D16: إعدادات الرسوم | E16: تم الدخول كمدير | F16: 1. تبويب «إعدادات الرسوم». 2. أدخل الرسم السنوي (مثلاً 30) والرسوم الشهرية (مثلاً 20). 3. احفظ. | G16: رسالة نجاح، والقيم محفوظة بعد التنقل. تظهر الملاحظات حول أثر تغيير الرسوم. | H16: أساسي | I16: =IFERROR(INDEX(الأقسام!$H$2:$H$14,MATCH(B16,الأقسام!$A$2:$A$14,0))&"","") | J16: لم يبدأ
A17: SET-05 | B17: SET | C17: =IFERROR(INDEX(الأقسام!$B$2:$B$14,MATCH(B17,الأقسام!$A$2:$A$14,0)),"") -> الإعدادات والفئات العمرية | D17: قيم رسوم غير صالحة | F17: 1. أدخل رقماً سالباً (مثلاً -10) في الرسوم الشهرية. 2. أدخل حروفاً بدل الأرقام. 3. احفظ. | G17: يرفض البرنامج القيم غير الصالحة برسالة واضحة. | H17: مهم | I17: =IFERROR(INDEX(الأقسام!$H$2:$H$14,MATCH(B17,الأقسام!$A$2:$A$14,0))&"","") | J17: لم يبدأ
A18: SET-06 | B18: SET | C18: =IFERROR(INDEX(الأقسام!$B$2:$B$14,MATCH(B18,الأقسام!$A$2:$A$14,0)),"") -> الإعدادات والفئات العمرية | D18: شهر بداية السنة الدراسية ويوم التوليد | F18: 1. غيّر «شهر بداية السنة الدراسية» (مثلاً إلى أكتوبر) واحفظ. 2. افتح الشؤون المالية ← رسوم الطلاب وراجع السنة الدراسية المعروضة. 3. أرجع الشهر إلى سبتمبر. 4. غيّر «يوم توليد رسوم الشهر القادم» (مثلاً 20) واحفظ. | G18: القيم تُحفظ، والسنة الدراسية المعروضة في رسوم الطلاب تتبع الشهر المختار. | H18: مهم | I18: =IFERROR(INDEX(الأقسام!$H$2:$H$14,MATCH(B18,الأقسام!$A$2:$A$14,0))&"","") | J18: لم يبدأ
A19: SET-07 | B19: SET | C19: =IFERROR(INDEX(الأقسام!$B$2:$B$14,MATCH(B19,الأقسام!$A$2:$A$14,0)),"") -> الإعدادات والفئات العمرية | D19: الفئات العمرية الافتراضية | F19: 1. افتح تبويب «فئات عمرية». 2. راجع الجدول: الاسم، النطاق العمري، النوع، نظام الدفع، الرسوم. | G19: تظهر الفئات الافتراضية (الأطفال، الناشئون...) مع نظام الدفع «شهري» والرسوم الافتراضية للفرع. | H19: مهم | I19: =IFERROR(INDEX(الأقسام!$H$2:$H$14,MATCH(B19,الأقسام!$A$2:$A$14,0))&"","") | J19: لم يبدأ
A20: SET-08 | B20: SET | C20: =IFERROR(INDEX(الأقسام!$B$2:$B$14,MATCH(B20,الأقسام!$A$2:$A$14,0)),"") -> الإعدادات والفئات العمرية | D20: إضافة فئة عمرية | F20: 1. اضغط «إضافة فئة جديدة». 2. الاسم: «الكبار»، النوع: الكل، العمر الأدنى 25، اترك الأقصى فارغاً. 3. نظام الدفع: سنوي، الرسوم السنوية: 60. 4. احفظ. | G20: تظهر الفئة في الجدول بالقيم المدخلة، والعمر الأقصى غير محدود. | H20: أساسي | I20: =IFERROR(INDEX(الأقسام!$H$2:$H$14,MATCH(B20,الأقسام!$A$2:$A$14,0))&"","") | J20: لم يبدأ
A21: SET-09 | B21: SET | C21: =IFERROR(INDEX(الأقسام!$B$2:$B$14,MATCH(B21,الأقسام!$A$2:$A$14,0)),"") -> الإعدادات والفئات العمرية | D21: التحقق من الأعمار في الفئة العمرية | F21: 1. أضف فئة عمرها الأدنى 15 والأقصى 10. 2. احفظ. | G21: رسالة خطأ: العمر الأقصى يجب أن يكون أكبر من الأدنى، ولا تُحفظ الفئة. | H21: مهم | I21: =IFERROR(INDEX(الأقسام!$H$2:$H$14,MATCH(B21,الأقسام!$A$2:$A$14,0))&"","") | J21: لم يبدأ
A22: SET-10 | B22: SET | C22: =IFERROR(INDEX(الأقسام!$B$2:$B$14,MATCH(B22,الأقسام!$A$2:$A$14,0)),"") -> الإعدادات والفئات العمرية | D22: تعديل فئة عمرية ورسومها | E22: فئة موجودة | F22: 1. اضغط «تعديل» على فئة. 2. غيّر الرسوم الشهرية إلى 25 ونظام الدفع. 3. احفظ. | G22: تُحفظ التعديلات وتظهر في الجدول. الملاحظة توضح أن التغيير يطبق من الفاتورة القادمة. | H22: مهم | I22: =IFERROR(INDEX(الأقسام!$H$2:$H$14,MATCH(B22,الأقسام!$A$2:$A$14,0))&"","") | J22: لم يبدأ
A23: SET-11 | B23: SET | C23: =IFERROR(INDEX(الأقسام!$B$2:$B$14,MATCH(B23,الأقسام!$A$2:$A$14,0)),"") -> الإعدادات والفئات العمرية | D23: حذف (إيقاف) فئة عمرية | E23: فئة غير مستعملة | F23: 1. اضغط «حذف» على فئة وأكّد. 2. افتح «إضافة فصل» وراجع قائمة الفئات العمرية. | G23: تختفي الفئة من القائمة ولا تظهر عند إنشاء فصل جديد. | H23: إضافي | I23: =IFERROR(INDEX(الأقسام!$H$2:$H$14,MATCH(B23,الأقسام!$A$2:$A$14,0))&"","") | J23: لم يبدأ
A24: USR-01 | B24: USR | C24: =IFERROR(INDEX(الأقسام!$B$2:$B$14,MATCH(B24,الأقسام!$A$2:$A$14,0)),"") -> المستخدمون والصلاحيات | D24: إضافة مستخدم «الهيئة المديرة» | E24: تم الدخول كمدير النظام | F24: 1. إدارة المستخدمين ← «إضافة مستخدم جديد». 2. املأ اسم المستخدم (بالإنجليزية) وكلمة المرور والاسم واللقب ورقم الهوية (8 أرقام) والهاتف (8 أرقام). 3. اختر الدور «الهيئة المديرة» واحفظ. | G24: يظهر المستخدم في الجدول بالدور الصحيح وحالة «نشط». | H24: أساسي | I24: =IFERROR(INDEX(الأقسام!$H$2:$H$14,MATCH(B24,الأقسام!$A$2:$A$14,0))&"","") | J24: لم يبدأ
A25: USR-02 | B25: USR | C25: =IFERROR(INDEX(الأقسام!$B$2:$B$14,MATCH(B25,الأقسام!$A$2:$A$14,0)),"") -> المستخدمون والصلاحيات | D25: إضافة «مسؤول مالي» و«مشرف حصص» | F25: 1. أضف مستخدماً بدور «مسؤول مالي» فقط. 2. أضف مستخدماً بدور «مشرف حصص» فقط. | G25: يظهر المستخدمان بأدوارهما الصحيحة. | H25: أساسي | I25: =IFERROR(INDEX(الأقسام!$H$2:$H$14,MATCH(B25,الأقسام!$A$2:$A$14,0))&"","") | J25: لم يبدأ
A26: USR-03 | B26: USR | C26: =IFERROR(INDEX(الأقسام!$B$2:$B$14,MATCH(B26,الأقسام!$A$2:$A$14,0)),"") -> المستخدمون والصلاحيات | D26: التحقق من حقول المستخدم | F26: 1. اسم مستخدم بالعربية. 2. كلمة مرور قصيرة. 3. هاتف من 7 أرقام. 4. اسم مستخدم مكرر (مستعمل من قبل). 5. بدون أي دور. | G26: رسالة خطأ واضحة لكل حالة، ولا يُحفظ المستخدم. | H26: مهم | I26: =IFERROR(INDEX(الأقسام!$H$2:$H$14,MATCH(B26,الأقسام!$A$2:$A$14,0))&"","") | J26: لم يبدأ
A27: USR-04 | B27: USR | C27: =IFERROR(INDEX(الأقسام!$B$2:$B$14,MATCH(B27,الأقسام!$A$2:$A$14,0)),"") -> المستخدمون والصلاحيات | D27: صلاحيات «الهيئة المديرة» | E27: مستخدم بهذا الدور | F27: 1. سجّل الخروج وادخل بحساب «الهيئة المديرة». 2. راجع القائمة الجانبية وجرّب كل صفحة. | G27: يرى الطلاب والمعلمين والفصول والحضور. لا يستطيع تعديل المستخدمين أو فتح ما هو خاص بمدير النظام. سجّل ما يظهر بالضبط في الملاحظات. | H27: أساسي | I27: =IFERROR(INDEX(الأقسام!$H$2:$H$14,MATCH(B27,الأقسام!$A$2:$A$14,0))&"","") | J27: لم يبدأ
A28: USR-05 | B28: USR | C28: =IFERROR(INDEX(الأقسام!$B$2:$B$14,MATCH(B28,الأقسام!$A$2:$A$14,0)),"") -> المستخدمون والصلاحيات | D28: صلاحيات «المسؤول المالي» | E28: مستخدم بهذا الدور | F28: 1. ادخل بحساب «مسؤول مالي». 2. راجع القائمة الجانبية وجرّب كل صفحة. | G28: يرى «الشؤون المالية» ويعمل فيها، ويرى الطلاب للاطلاع فقط (لا إضافة ولا تعديل ولا حذف). لا يرى الإعدادات ولا المستخدمين. | H28: أساسي | I28: =IFERROR(INDEX(الأقسام!$H$2:$H$14,MATCH(B28,الأقسام!$A$2:$A$14,0))&"","") | J28: لم يبدأ
A29: USR-06 | B29: USR | C29: =IFERROR(INDEX(الأقسام!$B$2:$B$14,MATCH(B29,الأقسام!$A$2:$A$14,0)),"") -> المستخدمون والصلاحيات | D29: صلاحيات «مشرف الحصص» | E29: مستخدم بهذا الدور | F29: 1. ادخل بحساب «مشرف حصص». 2. راجع القائمة الجانبية وجرّب كل صفحة. | G29: يرى «الحضور والغياب» ويسجل الحضور، ويرى الطلاب والفصول للاطلاع فقط. لا يرى الشؤون المالية ولا الإعدادات. | H29: أساسي | I29: =IFERROR(INDEX(الأقسام!$H$2:$H$14,MATCH(B29,الأقسام!$A$2:$A$14,0))&"","") | J29: لم يبدأ
A30: USR-07 | B30: USR | C30: =IFERROR(INDEX(الأقسام!$B$2:$B$14,MATCH(B30,الأقسام!$A$2:$A$14,0)),"") -> المستخدمون والصلاحيات | D30: تعديل مستخدم | E30: مستخدم موجود | F30: 1. اضغط «تعديل» على مستخدم. 2. غيّر الهاتف والدور، واترك كلمة المرور فارغة. 3. احفظ ثم ادخل بحسابه. | G30: تُحفظ التعديلات، وكلمة المرور القديمة ما زالت تعمل، والصلاحيات تتبع الدور الجديد. اسم المستخدم لا يمكن تغييره. | H30: مهم | I30: =IFERROR(INDEX(الأقسام!$H$2:$H$14,MATCH(B30,الأقسام!$A$2:$A$14,0))&"","") | J30: لم يبدأ
A31: USR-08 | B31: USR | C31: =IFERROR(INDEX(الأقسام!$B$2:$B$14,MATCH(B31,الأقسام!$A$2:$A$14,0)),"") -> المستخدمون والصلاحيات | D31: مستخدم «غير نشط» يحاول الدخول | E31: مستخدم موجود | F31: 1. عدّل مستخدماً واجعل حالته «غير نشط». 2. سجّل الخروج وحاول الدخول بحسابه. | G31: يجب ألا يتمكن المستخدم غير النشط من الدخول. (إن تمكن من الدخول، سجّل ذلك كخطأ.) | H31: أساسي | I31: =IFERROR(INDEX(الأقسام!$H$2:$H$14,MATCH(B31,الأقسام!$A$2:$A$14,0))&"","") | J31: لم يبدأ
A32: USR-09 | B32: USR | C32: =IFERROR(INDEX(الأقسام!$B$2:$B$14,MATCH(B32,الأقسام!$A$2:$A$14,0)),"") -> المستخدمون والصلاحيات | D32: حذف مستخدم | E32: مستخدم تجريبي | F32: 1. اضغط «حذف» على مستخدم وأكّد. 2. حاول الدخول بحسابه. | G32: يختفي من الجدول ولا يستطيع الدخول. | H32: مهم | I32: =IFERROR(INDEX(الأقسام!$H$2:$H$14,MATCH(B32,الأقسام!$A$2:$A$14,0))&"","") | J32: لم يبدأ
A33: USR-10 | B33: USR | C33: =IFERROR(INDEX(الأقسام!$B$2:$B$14,MATCH(B33,الأقسام!$A$2:$A$14,0)),"") -> المستخدمون والصلاحيات | D33: البحث والتصفية في المستخدمين | E33: 3 مستخدمين على الأقل | F33: 1. ابحث بجزء من الاسم. 2. صفِّ حسب «الدور» ثم حسب «الحالة». | G33: تظهر النتائج المطابقة فقط، وتعود القائمة كاملة عند مسح البحث. | H33: إضافي | I33: =IFERROR(INDEX(الأقسام!$H$2:$H$14,MATCH(B33,الأقسام!$A$2:$A$14,0))&"","") | J33: لم يبدأ
A34: USR-11 | B34: USR | C34: =IFERROR(INDEX(الأقسام!$B$2:$B$14,MATCH(B34,الأقسام!$A$2:$A$14,0)),"") -> المستخدمون والصلاحيات | D34: الملف الشخصي | E34: تم الدخول | F34: 1. افتح «ملفي الشخصي». 2. عدّل الهاتف والمهنة واضغط «حفظ معلوماتي». 3. أعد فتح الصفحة. | G34: رسالة نجاح والمعلومات محفوظة. | H34: مهم | I34: =IFERROR(INDEX(الأقسام!$H$2:$H$14,MATCH(B34,الأقسام!$A$2:$A$14,0))&"","") | J34: لم يبدأ
A35: USR-12 | B35: USR | C35: =IFERROR(INDEX(الأقسام!$B$2:$B$14,MATCH(B35,الأقسام!$A$2:$A$14,0)),"") -> المستخدمون والصلاحيات | D35: تغيير كلمة المرور | E35: تم الدخول | F35: 1. في «ملفي الشخصي»: أدخل كلمة مرور حالية خاطئة. 2. أدخل تأكيداً غير مطابق. 3. أدخل البيانات الصحيحة واحفظ. 4. اخرج وادخل بكلمة المرور الجديدة. | G35: رسالة خطأ في الحالتين الأوليين؛ ثم تنجح العملية والدخول يتم بكلمة المرور الجديدة فقط. | H35: أساسي | I35: =IFERROR(INDEX(الأقسام!$H$2:$H$14,MATCH(B35,الأقسام!$A$2:$A$14,0))&"","") | J35: لم يبدأ
A36: USR-13 | B36: USR | C36: =IFERROR(INDEX(الأقسام!$B$2:$B$14,MATCH(B36,الأقسام!$A$2:$A$14,0)),"") -> المستخدمون والصلاحيات | D36: تصدير واستيراد المستخدمين | E36: بعض المستخدمين | F36: 1. «تصدير البيانات» واختر الحقول والصيغة. 2. «استيراد البيانات» ← «إنشاء قالب»، املأ مستخدمين اثنين، ثم «بدء معالج الاستيراد». | G36: يُنشأ ملف التصدير بالعربية. الاستيراد يضيف المستخدمين ويعرض كلمات مرورهم المؤقتة. عند دخولهم أول مرة يُطلب منهم تغيير كلمة المرور إن كانت افتراضية. | H36: إضافي | I36: =IFERROR(INDEX(الأقسام!$H$2:$H$14,MATCH(B36,الأقسام!$A$2:$A$14,0))&"","") | J36: لم يبدأ
A37: TCH-01 | B37: TCH | C37: =IFERROR(INDEX(الأقسام!$B$2:$B$14,MATCH(B37,الأقسام!$A$2:$A$14,0)),"") -> المعلمون | D37: إضافة معلم | E37: تم الدخول كمدير | F37: 1. شؤون المعلمين ← «إضافة معلم». 2. املأ الاسم والهاتف (8 أرقام) والجنس وبقية الحقول. 3. احفظ. | G37: رسالة «تمت إضافة المعلم» ويظهر في الجدول مع رقم تعريفي. | H37: أساسي | I37: =IFERROR(INDEX(الأقسام!$H$2:$H$14,MATCH(B37,الأقسام!$A$2:$A$14,0))&"","") | J37: لم يبدأ
A38: TCH-02 | B38: TCH | C38: =IFERROR(INDEX(الأقسام!$B$2:$B$14,MATCH(B38,الأقسام!$A$2:$A$14,0)),"") -> المعلمون | D38: التحقق من حقول المعلم | F38: 1. هاتف من 7 أرقام. 2. بدون اسم. 3. بريد إلكتروني غير صالح (مثلاً abc). 4. رقم هوية من 5 أرقام. | G38: رسالة خطأ لكل حالة، والنافذة تبقى مفتوحة، ولا يُضاف المعلم. | H38: أساسي | I38: =IFERROR(INDEX(الأقسام!$H$2:$H$14,MATCH(B38,الأقسام!$A$2:$A$14,0))&"","") | J38: لم يبدأ
A39: TCH-03 | B39: TCH | C39: =IFERROR(INDEX(الأقسام!$B$2:$B$14,MATCH(B39,الأقسام!$A$2:$A$14,0)),"") -> المعلمون | D39: البحث والتصفية | E39: 3 معلمين على الأقل | F39: 1. ابحث بجزء من الاسم ثم بالرقم التعريفي. 2. صفِّ حسب الجنس. 3. امسح البحث. | G39: تظهر النتائج المطابقة فقط، ورسالة «لا توجد نتائج» عند عدم التطابق، وتعود القائمة كاملة. | H39: مهم | I39: =IFERROR(INDEX(الأقسام!$H$2:$H$14,MATCH(B39,الأقسام!$A$2:$A$14,0))&"","") | J39: لم يبدأ
A40: TCH-04 | B40: TCH | C40: =IFERROR(INDEX(الأقسام!$B$2:$B$14,MATCH(B40,الأقسام!$A$2:$A$14,0)),"") -> المعلمون | D40: عرض تفاصيل معلم | E40: معلم موجود | F40: 1. اضغط «عرض التفاصيل». | G40: تظهر كل المعلومات المدخلة بشكل صحيح. | H40: إضافي | I40: =IFERROR(INDEX(الأقسام!$H$2:$H$14,MATCH(B40,الأقسام!$A$2:$A$14,0))&"","") | J40: لم يبدأ
A41: TCH-05 | B41: TCH | C41: =IFERROR(INDEX(الأقسام!$B$2:$B$14,MATCH(B41,الأقسام!$A$2:$A$14,0)),"") -> المعلمون | D41: تعديل معلم | E41: معلم موجود | F41: 1. اضغط «تعديل»، غيّر الاسم والهاتف واحفظ. | G41: رسالة نجاح والتعديلات ظاهرة في الجدول وفي الفصول المسندة إليه. | H41: مهم | I41: =IFERROR(INDEX(الأقسام!$H$2:$H$14,MATCH(B41,الأقسام!$A$2:$A$14,0))&"","") | J41: لم يبدأ
A42: TCH-06 | B42: TCH | C42: =IFERROR(INDEX(الأقسام!$B$2:$B$14,MATCH(B42,الأقسام!$A$2:$A$14,0)),"") -> المعلمون | D42: حذف معلم مسند إلى فصل | E42: معلم مسند إلى فصل | F42: 1. احذف معلماً مسنداً إلى فصل. 2. افتح الفصل. | G42: يُحذف المعلم (أو يرفض البرنامج الحذف برسالة واضحة). الفصل يبقى ويظهر بدون معلم. سجّل السلوك في الملاحظات. | H42: مهم | I42: =IFERROR(INDEX(الأقسام!$H$2:$H$14,MATCH(B42,الأقسام!$A$2:$A$14,0))&"","") | J42: لم يبدأ
...

Sheet الأخطاء والملاحظات
A1: رقم الخطأ | B1: التاريخ | C1: المبلّغ | D1: رقم الاختبار | E1: الخطورة | F1: ماذا فعلت؟ (الخطوات) | G1: ماذا حدث؟ | H1: ماذا كنت تتوقع؟ | I1: لقطة الشاشة (رابط أو «واتساب») | J1: حالة المعالجة (للمطوّر) | K1: رد المطوّر
A2: B-001
A3: B-002
A4: B-003
A5: B-004
A6: B-005
A7: B-006
A8: B-007
A9: B-008
A10: B-009
A11: B-010
A12: B-011
A13: B-012
... A301: B-300

Sheet المختبرون
A1: الاسم | B1: الهاتف | C1: الجهاز (Windows 10/11) | D1: الأقسام المحجوزة | E1: اختباراتي | F1: نجح | G1: فشل | H1: المنجز | I1: الأخطاء المسجلة
D2: =IF(A2="","",COUNTIF(الأقسام!$H$2:$H$100,A2)) | E2: =IF(A2="","",COUNTIF(الاختبارات!$I$2:$I$1000,A2)) | F2: =IF(A2="","",COUNTIFS(الاختبارات!$I$2:$I$1000,A2,الاختبارات!$J$2:$J$1000,"نجح")) | G2: =IF(A2="","",COUNTIFS(الاختبارات!$I$2:$I$1000,A2,الاختبارات!$J$2:$J$1000,"فشل")) | H2: =IF(OR(A2="",E2=0),"",(F2+G2)/E2) | I2: =IF(A2="","",COUNTIF('الأخطاء والملاحظات'!$C$2:$C$301,A2))
D3: =IF(A3="","",COUNTIF(الأقسام!$H$2:$H$100,A3)) | E3: =IF(A3="","",COUNTIF(الاختبارات!$I$2:$I$1000,A3)) | F3: =IF(A3="","",COUNTIFS(الاختبارات!$I$2:$I$1000,A3,الاختبارات!$J$2:$J$1000,"نجح")) | G3: =IF(A3="","",COUNTIFS(الاختبارات!$I$2:$I$1000,A3,الاختبارات!$J$2:$J$1000,"فشل")) | H3: =IF(OR(A3="",E3=0),"",(F3+G3)/E3) | I3: =IF(A3="","",COUNTIF('الأخطاء والملاحظات'!$C$2:$C$301,A3))
D4: =IF(A4="","",COUNTIF(الأقسام!$H$2:$H$100,A4)) | E4: =IF(A4="","",COUNTIF(الاختبارات!$I$2:$I$1000,A4)) | F4: =IF(A4="","",COUNTIFS(الاختبارات!$I$2:$I$1000,A4,الاختبارات!$J$2:$J$1000,"نجح")) | G4: =IF(A4="","",COUNTIFS(الاختبارات!$I$2:$I$1000,A4,الاختبارات!$J$2:$J$1000,"فشل")) | H4: =IF(OR(A4="",E4=0),"",(F4+G4)/E4) | I4: =IF(A4="","",COUNTIF('الأخطاء والملاحظات'!$C$2:$C$301,A4))
D5: =IF(A5="","",COUNTIF(الأقسام!$H$2:$H$100,A5)) | E5: =IF(A5="","",COUNTIF(الاختبارات!$I$2:$I$1000,A5)) | F5: =IF(A5="","",COUNTIFS(الاختبارات!$I$2:$I$1000,A5,الاختبارات!$J$2:$J$1000,"نجح")) | G5: =IF(A5="","",COUNTIFS(الاختبارات!$I$2:$I$1000,A5,الاختبارات!$J$2:$J$1000,"فشل")) | H5: =IF(OR(A5="",E5=0),"",(F5+G5)/E5) | I5: =IF(A5="","",COUNTIF('الأخطاء والملاحظات'!$C$2:$C$301,A5))
D6: =IF(A6="","",COUNTIF(الأقسام!$H$2:$H$100,A6)) | E6: =IF(A6="","",COUNTIF(الاختبارات!$I$2:$I$1000,A6)) | F6: =IF(A6="","",COUNTIFS(الاختبارات!$I$2:$I$1000,A6,الاختبارات!$J$2:$J$1000,"نجح")) | G6: =IF(A6="","",COUNTIFS(الاختبارات!$I$2:$I$1000,A6,الاختبارات!$J$2:$J$1000,"فشل")) | H6: =IF(OR(A6="",E6=0),"",(F6+G6)/E6) | I6: =IF(A6="","",COUNTIF('الأخطاء والملاحظات'!$C$2:$C$301,A6))
D7: =IF(A7="","",COUNTIF(الأقسام!$H$2:$H$100,A7)) | E7: =IF(A7="","",COUNTIF(الاختبارات!$I$2:$I$1000,A7)) | F7: =IF(A7="","",COUNTIFS(الاختبارات!$I$2:$I$1000,A7,الاختبارات!$J$2:$J$1000,"نجح")) | G7: =IF(A7="","",COUNTIFS(الاختبارات!$I$2:$I$1000,A7,الاختبارات!$J$2:$J$1000,"فشل")) | H7: =IF(OR(A7="",E7=0),"",(F7+G7)/E7) | I7: =IF(A7="","",COUNTIF('الأخطاء والملاحظات'!$C$2:$C$301,A7))
D8: =IF(A8="","",COUNTIF(الأقسام!$H$2:$H$100,A8)) | E8: =IF(A8="","",COUNTIF(الاختبارات!$I$2:$I$1000,A8)) | F8: =IF(A8="","",COUNTIFS(الاختبارات!$I$2:$I$1000,A8,الاختبارات!$J$2:$J$1000,"نجح")) | G8: =IF(A8="","",COUNTIFS(الاختبارات!$I$2:$I$1000,A8,الاختبارات!$J$2:$J$1000,"فشل")) | H8: =IF(OR(A8="",E8=0),"",(F8+G8)/E8) | I8: =IF(A8="","",COUNTIF('الأخطاء والملاحظات'!$C$2:$C$301,A8))
D9: =IF(A9="","",COUNTIF(الأقسام!$H$2:$H$100,A9)) | E9: =IF(A9="","",COUNTIF(الاختبارات!$I$2:$I$1000,A9)) | F9: =IF(A9="","",COUNTIFS(الاختبارات!$I$2:$I$1000,A9,الاختبارات!$J$2:$J$1000,"نجح")) | G9: =IF(A9="","",COUNTIFS(الاختبارات!$I$2:$I$1000,A9,الاختبارات!$J$2:$J$1000,"فشل")) | H9: =IF(OR(A9="",E9=0),"",(F9+G9)/E9) | I9: =IF(A9="","",COUNTIF('الأخطاء والملاحظات'!$C$2:$C$301,A9))
D10: =IF(A10="","",COUNTIF(الأقسام!$H$2:$H$100,A10)) | E10: =IF(A10="","",COUNTIF(الاختبارات!$I$2:$I$1000,A10)) | F10: =IF(A10="","",COUNTIFS(الاختبارات!$I$2:$I$1000,A10,الاختبارات!$J$2:$J$1000,"نجح")) | G10: =IF(A10="","",COUNTIFS(الاختبارات!$I$2:$I$1000,A10,الاختبارات!$J$2:$J$1000,"فشل")) | H10: =IF(OR(A10="",E10=0),"",(F10+G10)/E10) | I10: =IF(A10="","",COUNTIF('الأخطاء والملاحظات'!$C$2:$C$301,A10))
D11: =IF(A11="","",COUNTIF(الأقسام!$H$2:$H$100,A11)) | E11: =IF(A11="","",COUNTIF(الاختبارات!$I$2:$I$1000,A11)) | F11: =IF(A11="","",COUNTIFS(الاختبارات!$I$2:$I$1000,A11,الاختبارات!$J$2:$J$1000,"نجح")) | G11: =IF(A11="","",COUNTIFS(الاختبارات!$I$2:$I$1000,A11,الاختبارات!$J$2:$J$1000,"فشل")) | H11: =IF(OR(A11="",E11=0),"",(F11+G11)/E11) | I11: =IF(A11="","",COUNTIF('الأخطاء والملاحظات'!$C$2:$C$301,A11))
D12: =IF(A12="","",COUNTIF(الأقسام!$H$2:$H$100,A12)) | E12: =IF(A12="","",COUNTIF(الاختبارات!$I$2:$I$1000,A12)) | F12: =IF(A12="","",COUNTIFS(الاختبارات!$I$2:$I$1000,A12,الاختبارات!$J$2:$J$1000,"نجح")) | G12: =IF(A12="","",COUNTIFS(الاختبارات!$I$2:$I$1000,A12,الاختبارات!$J$2:$J$1000,"فشل")) | H12: =IF(OR(A12="",E12=0),"",(F12+G12)/E12) | I12: =IF(A12="","",COUNTIF('الأخطاء والملاحظات'!$C$2:$C$301,A12))
D13: =IF(A13="","",COUNTIF(الأقسام!$H$2:$H$100,A13)) | E13: =IF(A13="","",COUNTIF(الاختبارات!$I$2:$I$1000,A13)) | F13: =IF(A13="","",COUNTIFS(الاختبارات!$I$2:$I$1000,A13,الاختبارات!$J$2:$J$1000,"نجح")) | G13: =IF(A13="","",COUNTIFS(الاختبارات!$I$2:$I$1000,A13,الاختبارات!$J$2:$J$1000,"فشل")) | H13: =IF(OR(A13="",E13=0),"",(F13+G13)/E13) | I13: =IF(A13="","",COUNTIF('الأخطاء والملاحظات'!$C$2:$C$301,A13))
... D41: =IF(A41="","",COUNTIF(الأقسام!$H$2:$H$100,A41)) | E41: =IF(A41="","",COUNTIF(الاختبارات!$I$2:$I$1000,A41)) | F41: =IF(A41="","",COUNTIFS(الاختبارات!$I$2:$I$1000,A41,الاختبارات!$J$2:$J$1000,"نجح")) | G41: =IF(A41="","",COUNTIFS(الاختبارات!$I$2:$I$1000,A41,الاختبارات!$J$2:$J$1000,"فشل")) | H41: =IF(OR(A41="",E41=0),"",(F41+G41)/E41) | I41: =IF(A41="","",COUNTIF('الأخطاء والملاحظات'!$C$2:$C$301,A41))

Sheet المتابعة
A1: متابعة الاختبار
B3: العدد | C3: النسبة
A4: كل الاختبارات | B4: =COUNTA(الاختبارات!$A$2:$A$140) -> 139 | C4: =IF($B$4=0,0,B4/$B$4) -> 1
A5: نجح | B5: =COUNTIF(الاختبارات!$J$2:$J$140,"نجح") -> 0 | C5: =IF($B$4=0,0,B5/$B$4) -> 0
A6: فشل | B6: =COUNTIF(الاختبارات!$J$2:$J$140,"فشل") -> 0 | C6: =IF($B$4=0,0,B6/$B$4) -> 0
A7: متوقف | B7: =COUNTIF(الاختبارات!$J$2:$J$140,"متوقف") -> 0 | C7: =IF($B$4=0,0,B7/$B$4) -> 0
A8: قيد التنفيذ | B8: =COUNTIF(الاختبارات!$J$2:$J$140,"قيد التنفيذ") -> 0 | C8: =IF($B$4=0,0,B8/$B$4) -> 0
A9: لم يبدأ | B9: =B4-B5-B6-B7-B8 -> 139 | C9: =IF($B$4=0,0,B9/$B$4) -> 1
A11: التقدم العام (نجح + فشل) | B11: =IF(B4=0,0,(B5+B6)/B4) -> 0
A12: الاختبارات الأساسية المنجزة | B12: =COUNTIFS(الاختبارات!$H$2:$H$140,"أساسي",الاختبارات!$J$2:$J$140,"نجح")+COUNTIFS(الاختبارات!$H$2:$H$140,"أساسي",الاختبارات!$J$2:$J$140,"فشل") -> 0 | C12: =COUNTIF(الاختبارات!$H$2:$H$140,"أساسي") -> 58 | D12: من
A14: القسم | B14: المختبِر | C14: الاختبارات | D14: نجح | E14: فشل | F14: متوقف | G14: التقدم | H14: الحالة
A15: =الأقسام!B2 -> التثبيت وأول تشغيل | B15: =الأقسام!H2&"" | C15: =الأقسام!J2 -> 11 | D15: =الأقسام!K2 -> 0 | E15: =الأقسام!L2 -> 0 | F15: =الأقسام!M2 -> 0 | G15: =الأقسام!O2 -> 0 | H15: =الأقسام!P2 -> متاح للحجز
A16: =الأقسام!B3 -> الإعدادات والفئات العمرية | B16: =الأقسام!H3&"" | C16: =الأقسام!J3 -> 11 | D16: =الأقسام!K3 -> 0 | E16: =الأقسام!L3 -> 0 | F16: =الأقسام!M3 -> 0 | G16: =الأقسام!O3 -> 0 | H16: =الأقسام!P3 -> متاح للحجز
A17: =الأقسام!B4 -> المستخدمون والصلاحيات | B17: =الأقسام!H4&"" | C17: =الأقسام!J4 -> 13 | D17: =الأقسام!K4 -> 0 | E17: =الأقسام!L4 -> 0 | F17: =الأقسام!M4 -> 0 | G17: =الأقسام!O4 -> 0 | H17: =الأقسام!P4 -> متاح للحجز
A18: =الأقسام!B5 -> المعلمون | B18: =الأقسام!H5&"" | C18: =الأقسام!J5 -> 8 | D18: =الأقسام!K5 -> 0 | E18: =الأقسام!L5 -> 0 | F18: =الأقسام!M5 -> 0 | G18: =الأقسام!O5 -> 0 | H18: =الأقسام!P5 -> متاح للحجز
A19: =الأقسام!B6 -> الطلاب | B19: =الأقسام!H6&"" | C19: =الأقسام!J6 -> 16 | D19: =الأقسام!K6 -> 0 | E19: =الأقسام!L6 -> 0 | F19: =الأقسام!M6 -> 0 | G19: =الأقسام!O6 -> 0 | H19: =الأقسام!P6 -> متاح للحجز
A20: =الأقسام!B7 -> الفصول وتسجيل الطلاب | B20: =الأقسام!H7&"" | C20: =الأقسام!J7 -> 12 | D20: =الأقسام!K7 -> 0 | E20: =الأقسام!L7 -> 0 | F20: =الأقسام!M7 -> 0 | G20: =الأقسام!O7 -> 0 | H20: =الأقسام!P7 -> متاح للحجز
A21: =الأقسام!B8 -> الحضور والغياب | B21: =الأقسام!H8&"" | C21: =الأقسام!J8 -> 9 | D21: =الأقسام!K8 -> 0 | E21: =الأقسام!L8 -> 0 | F21: =الأقسام!M8 -> 0 | G21: =الأقسام!O8 -> 0 | H21: =الأقسام!P8 -> متاح للحجز
A22: =الأقسام!B9 -> رسوم الطلاب والدفعات | B22: =الأقسام!H9&"" | C22: =الأقسام!J9 -> 21 | D22: =الأقسام!K9 -> 0 | E22: =الأقسام!L9 -> 0 | F22: =الأقسام!M9 -> 0 | G22: =الأقسام!O9 -> 0 | H22: =الأقسام!P9 -> متاح للحجز
A23: =الأقسام!B10 -> المداخيل والمصاريف ولوحة التحكم المالية | B23: =الأقسام!H10&"" | C23: =الأقسام!J10 -> 12 | D23: =الأقسام!K10 -> 0 | E23: =الأقسام!L10 -> 0 | F23: =الأقسام!M10 -> 0 | G23: =الأقسام!O10 -> 0 | H23: =الأقسام!P10 -> متاح للحجز
A24: =الأقسام!B11 -> الجرد والتبرعات العينية | B24: =الأقسام!H11&"" | C24: =الأقسام!J11 -> 6 | D24: =الأقسام!K11 -> 0 | E24: =الأقسام!L11 -> 0 | F24: =الأقسام!M11 -> 0 | G24: =الأقسام!O11 -> 0 | H24: =الأقسام!P11 -> متاح للحجز
A25: =الأقسام!B12 -> التقارير والتصدير | B25: =الأقسام!H12&"" | C25: =الأقسام!J12 -> 6 | D25: =الأقسام!K12 -> 0 | E25: =الأقسام!L12 -> 0 | F25: =الأقسام!M12 -> 0 | G25: =الأقسام!O12 -> 0 | H25: =الأقسام!P12 -> متاح للحجز
A26: =الأقسام!B13 -> النسخ الاحتياطي والاستعادة | B26: =الأقسام!H13&"" | C26: =الأقسام!J13 -> 8 | D26: =الأقسام!K13 -> 0 | E26: =الأقسام!L13 -> 0 | F26: =الأقسام!M13 -> 0 | G26: =الأقسام!O13 -> 0 | H26: =الأقسام!P13 -> متاح للحجز
A27: =الأقسام!B14 -> الاستعمال العام والاستكشاف الحر | B27: =الأقسام!H14&"" | C27: =الأقسام!J14 -> 6 | D27: =الأقسام!K14 -> 0 | E27: =الأقسام!L14 -> 0 | F27: =الأقسام!M14 -> 0 | G27: =الأقسام!O14 -> 0 | H27: =الأقسام!P14 -> متاح للحجز
A29: الأخطاء | B29: المجموع | C29: عاجل | D29: مهم | E29: بسيط | F29: اقتراح
A30: كل الأخطاء | B30: =COUNTIF('الأخطاء والملاحظات'!$F$2:$F$301,"?*") -> 0 | C30: =COUNTIF('الأخطاء والملاحظات'!$E$2:$E$301,"عاجل") -> 0 | D30: =COUNTIF('الأخطاء والملاحظات'!$E$2:$E$301,"مهم") -> 0 | E30: =COUNTIF('الأخطاء والملاحظات'!$E$2:$E$301,"بسيط") -> 0 | F30: =COUNTIF('الأخطاء والملاحظات'!$E$2:$E$301,"اقتراح") -> 0
A31: جديد (لم يُعالج) | B31: =COUNTIFS('الأخطاء والملاحظات'!$F$2:$F$301,"?*",'الأخطاء والملاحظات'!$J$2:$J$301,"")+COUNTIF('الأخطاء والملاحظات'!$J$2:$J$301,"جديد") -> 0 | C31: =COUNTIFS('الأخطاء والملاحظات'!$E$2:$E$301,"عاجل",'الأخطاء والملاحظات'!$J$2:$J$301,"")+COUNTIFS('الأخطاء والملاحظات'!$E$2:$E$301,"عاجل",'الأخطاء والملاحظات'!$J$2:$J$301,"جديد") -> 0 | D31: =COUNTIFS('الأخطاء والملاحظات'!$E$2:$E$301,"مهم",'الأخطاء والملاحظات'!$J$2:$J$301,"")+COUNTIFS('الأخطاء والملاحظات'!$E$2:$E$301,"مهم",'الأخطاء والملاحظات'!$J$2:$J$301,"جديد") -> 0 | E31: =COUNTIFS('الأخطاء والملاحظات'!$E$2:$E$301,"بسيط",'الأخطاء والملاحظات'!$J$2:$J$301,"")+COUNTIFS('الأخطاء والملاحظات'!$E$2:$E$301,"بسيط",'الأخطاء والملاحظات'!$J$2:$J$301,"جديد") -> 0 | F31: =COUNTIFS('الأخطاء والملاحظات'!$E$2:$E$301,"اقتراح",'الأخطاء والملاحظات'!$J$2:$J$301,"")+COUNTIFS('الأخطاء والملاحظات'!$E$2:$E$301,"اقتراح",'الأخطاء والملاحظات'!$J$2:$J$301,"جديد") -> 0
A32: قيد الإصلاح | B32: =COUNTIF('الأخطاء والملاحظات'!$J$2:$J$301,"قيد الإصلاح") -> 0 | C32: =COUNTIFS('الأخطاء والملاحظات'!$E$2:$E$301,"عاجل",'الأخطاء والملاحظات'!$J$2:$J$301,"قيد الإصلاح") -> 0 | D32: =COUNTIFS('الأخطاء والملاحظات'!$E$2:$E$301,"مهم",'الأخطاء والملاحظات'!$J$2:$J$301,"قيد الإصلاح") -> 0 | E32: =COUNTIFS('الأخطاء والملاحظات'!$E$2:$E$301,"بسيط",'الأخطاء والملاحظات'!$J$2:$J$301,"قيد الإصلاح") -> 0 | F32: =COUNTIFS('الأخطاء والملاحظات'!$E$2:$E$301,"اقتراح",'الأخطاء والملاحظات'!$J$2:$J$301,"قيد الإصلاح") -> 0
A33: تم الإصلاح | B33: =COUNTIF('الأخطاء والملاحظات'!$J$2:$J$301,"تم الإصلاح") -> 0 | C33: =COUNTIFS('الأخطاء والملاحظات'!$E$2:$E$301,"عاجل",'الأخطاء والملاحظات'!$J$2:$J$301,"تم الإصلاح") -> 0 | D33: =COUNTIFS('الأخطاء والملاحظات'!$E$2:$E$301,"مهم",'الأخطاء والملاحظات'!$J$2:$J$301,"تم الإصلاح") -> 0 | E33: =COUNTIFS('الأخطاء والملاحظات'!$E$2:$E$301,"بسيط",'الأخطاء والملاحظات'!$J$2:$J$301,"تم الإصلاح") -> 0 | F33: =COUNTIFS('الأخطاء والملاحظات'!$E$2:$E$301,"اقتراح",'الأخطاء والملاحظات'!$J$2:$J$301,"تم الإصلاح") -> 0
A34: يحتاج توضيح | B34: =COUNTIF('الأخطاء والملاحظات'!$J$2:$J$301,"يحتاج توضيح") -> 0 | C34: =COUNTIFS('الأخطاء والملاحظات'!$E$2:$E$301,"عاجل",'الأخطاء والملاحظات'!$J$2:$J$301,"يحتاج توضيح") -> 0 | D34: =COUNTIFS('الأخطاء والملاحظات'!$E$2:$E$301,"مهم",'الأخطاء والملاحظات'!$J$2:$J$301,"يحتاج توضيح") -> 0 | E34: =COUNTIFS('الأخطاء والملاحظات'!$E$2:$E$301,"بسيط",'الأخطاء والملاحظات'!$J$2:$J$301,"يحتاج توضيح") -> 0 | F34: =COUNTIFS('الأخطاء والملاحظات'!$E$2:$E$301,"اقتراح",'الأخطاء والملاحظات'!$J$2:$J$301,"يحتاج توضيح") -> 0
A35: لن يُصلح | B35: =COUNTIF('الأخطاء والملاحظات'!$J$2:$J$301,"لن يُصلح") -> 0 | C35: =COUNTIFS('الأخطاء والملاحظات'!$E$2:$E$301,"عاجل",'الأخطاء والملاحظات'!$J$2:$J$301,"لن يُصلح") -> 0 | D35: =COUNTIFS('الأخطاء والملاحظات'!$E$2:$E$301,"مهم",'الأخطاء والملاحظات'!$J$2:$J$301,"لن يُصلح") -> 0 | E35: =COUNTIFS('الأخطاء والملاحظات'!$E$2:$E$301,"بسيط",'الأخطاء والملاحظات'!$J$2:$J$301,"لن يُصلح") -> 0 | F35: =COUNTIFS('الأخطاء والملاحظات'!$E$2:$E$301,"اقتراح",'الأخطاء والملاحظات'!$J$2:$J$301,"لن يُصلح") -> 0
A37: المختبِر | B37: الأقسام | C37: اختباراته | D37: نجح | E37: فشل | F37: المنجز | G37: الأخطاء المسجلة
A38: =المختبرون!A2&"" | B38: =IF(المختبرون!$A2="","",المختبرون!D2) | C38: =IF(المختبرون!$A2="","",المختبرون!E2) | D38: =IF(المختبرون!$A2="","",المختبرون!F2) | E38: =IF(المختبرون!$A2="","",المختبرون!G2) | F38: =IF(المختبرون!$A2="","",المختبرون!H2) | G38: =IF(المختبرون!$A2="","",المختبرون!I2)
A39: =المختبرون!A3&"" | B39: =IF(المختبرون!$A3="","",المختبرون!D3) | C39: =IF(المختبرون!$A3="","",المختبرون!E3) | D39: =IF(المختبرون!$A3="","",المختبرون!F3) | E39: =IF(المختبرون!$A3="","",المختبرون!G3) | F39: =IF(المختبرون!$A3="","",المختبرون!H3) | G39: =IF(المختبرون!$A3="","",المختبرون!I3)
A40: =المختبرون!A4&"" | B40: =IF(المختبرون!$A4="","",المختبرون!D4) | C40: =IF(المختبرون!$A4="","",المختبرون!E4) | D40: =IF(المختبرون!$A4="","",المختبرون!F4) | E40: =IF(المختبرون!$A4="","",المختبرون!G4) | F40: =IF(المختبرون!$A4="","",المختبرون!H4) | G40: =IF(المختبرون!$A4="","",المختبرون!I4)
A41: =المختبرون!A5&"" | B41: =IF(المختبرون!$A5="","",المختبرون!D5) | C41: =IF(المختبرون!$A5="","",المختبرون!E5) | D41: =IF(المختبرون!$A5="","",المختبرون!F5) | E41: =IF(المختبرون!$A5="","",المختبرون!G5) | F41: =IF(المختبرون!$A5="","",المختبرون!H5) | G41: =IF(المختبرون!$A5="","",المختبرون!I5)
A42: =المختبرون!A6&"" | B42: =IF(المختبرون!$A6="","",المختبرون!D6) | C42: =IF(المختبرون!$A6="","",المختبرون!E6) | D42: =IF(المختبرون!$A6="","",المختبرون!F6) | E42: =IF(المختبرون!$A6="","",المختبرون!G6) | F42: =IF(المختبرون!$A6="","",المختبرون!H6) | G42: =IF(المختبرون!$A6="","",المختبرون!I6)
A43: =المختبرون!A7&"" | B43: =IF(المختبرون!$A7="","",المختبرون!D7) | C43: =IF(المختبرون!$A7="","",المختبرون!E7) | D43: =IF(المختبرون!$A7="","",المختبرون!F7) | E43: =IF(المختبرون!$A7="","",المختبرون!G7) | F43: =IF(المختبرون!$A7="","",المختبرون!H7) | G43: =IF(المختبرون!$A7="","",المختبرون!I7)
A44: =المختبرون!A8&"" | B44: =IF(المختبرون!$A8="","",المختبرون!D8) | C44: =IF(المختبرون!$A8="","",المختبرون!E8) | D44: =IF(المختبرون!$A8="","",المختبرون!F8) | E44: =IF(المختبرون!$A8="","",المختبرون!G8) | F44: =IF(المختبرون!$A8="","",المختبرون!H8) | G44: =IF(المختبرون!$A8="","",المختبرون!I8)
A45: =المختبرون!A9&"" | B45: =IF(المختبرون!$A9="","",المختبرون!D9) | C45: =IF(المختبرون!$A9="","",المختبرون!E9) | D45: =IF(المختبرون!$A9="","",المختبرون!F9) | E45: =IF(المختبرون!$A9="","",المختبرون!G9) | F45: =IF(المختبرون!$A9="","",المختبرون!H9) | G45: =IF(المختبرون!$A9="","",المختبرون!I9)
...
